Workbook

Sheet Legend
A1: Category-wise steps for confirmed programs
A2: Legend for time-limits within which things need to be done:
A4: Symbol | B4: Meaning | C4: Date | D4: Notes | E4: Milestone
A5: R | B5: stands for date of receiving RFP | C5: 46113 | D5: Input actual date of receiving RFP | E5: Working on RFP
A6: R+ | B6: stands for no. of days after receiving RFP
A7: S | B7: stands for proposal submission date | C7: =$C$5+15 -> 46128 | D7: Input actual deadline of submitting proposal or Actual date of submitting proposal | E7: Working on RFP
A8: S-/+ | B8: stands for no. of days before/after proposal submission date
A9: W | B9: stands for date when client approves our proposal | D9: Input actual date when program is won | E9: Planning
A10: C | B10: stands for date of confirmation (for repeat clients, this can be when they tell us group size) | C10: 46130 | D10: Input actual date of program confirmation | E10: Planning
A11: C+ | B11: stands for no. of days after confirmation/go-ahead received from client
A12: P | B12: stands for program dates | C12: 46147 | D12: Input actual program start date | E12: Delivery
A13: PE | B13: stands for program end date | C13: 46157 | D13: Input actual program end date | E13: Delivery
A14: P- | B14: stands for no. of days before program start
A15: P+ | B15: stands for no. of days after the program ends

Sheet Faculty Led Programs
A1: Operations Process (Proposal to Delivery)
A3: Action Items while sending proposals
A4: Name | B4: Timeframe (Date) | C4: Timeframe (Date) | D4: Milestone | E4: Notes | F4: Process # | G4: Timeline - Start | H4: Timeline - End
A5: Ensure sales hand-off template is filled; clarify doubts, if any before working on the proposal | B5: R+1 | C5: =Legend!$C$5+1 -> 46114 | D5: Working on RFP | E5: Hand-off to ops team
A6: Detail out the requirements and send it to DMCs/Vendors | B6: R+2 | C6: =Legend!$C$5+2 -> 46115 | D6: Working on RFP | E6: Using draft itinerary template
A7: Create a costing sheet with quotes from DMCs/hotels | B7: R+7 | C7: =Legend!$C$5+7 -> 46120 | D7: Working on RFP
A8: Complete and review the costing sheet and proposal | B8: R+9 | C8: =Legend!$C$5+9 -> 46122 | D8: Working on RFP | E8: Use formats like hotel sheet to finalize hotel options
A9: Submit proposal to client | B9: S | C9: =Legend!$C$7 -> 46128 | D9: Working on RFP | E9: Sales team submits the proposal
A10: Block all proposed hotels and guides | B10: S | C10: =Legend!$C$7 -> 46128 | D10: Working on RFP | E10: ensure payments & cancellation are on agreeable terms
A11: Followup with client/sales on the proposal status to release or keep the blocks | B11: S+10 | C11: =Legend!$C$7+10 -> 46138 | D11: Working on RFP | E11: Proposal confirmation timeline could vary
A13: Action Items after proposal is won
A14: Name | B14: Timeframe (Date) | C14: Timeframe (Date) | D14: Milestone | E14: Notes | F14: Process # | G14: Timeline - Start | H14: Timeline - End
A15: Sign contracts with hotels and DMCs | B15: W+1 | C15: =Legend!$C$9+1 -> 1 | D15: Planning | E15: timeframe could vary
A16: Followup with client/sales on program confirmation date | B16: P-76 | C16: =Legend!$C$12-76 -> 46071 | D16: Planning | E16: timeframe could vary
A18: Action Items after program confirmation
A19: Name | B19: Timeframe (Date) | C19: Timeframe (Date) | D19: Milestone | E19: Notes | F19: Process # | G19: Timeline - Start | H19: Timeline - End
A20: Send deposit invoice to university | B20: P-76 | C20: =Legend!$C$12-76 -> 46071 | D20: Planning | E20: Check proposal terms and conditions
A21: Create mastersheet | B21: C+3 | C21: =Legend!$C$10+3 -> 46133 | D21: Planning | E21: Use template and fill information on an on-going basis
A22: Set up Monday.com/google sheet for collaboration with all university stakeholders | B22: C+3 | C22: =Legend!$C$10+3 -> 46133 | D22: Planning | E22: ENHANCED: Real-time tracking
A23: Share participant data template to collect information (including scanned passport copies) | B23: C+7 | C23: =Legend!$C$10+7 -> 46137 | D23: Planning | E23: Use participant data template #to client
A24: Send balance invoice to university | B24: P-32 | C24: =Legend!$C$12-32 -> 46115 | D24: Planning
A25: Get confirmation on final service requirements from university | B25: P-32 | C25: =Legend!$C$12-32 -> 46115 | D25: Planning | E25: Confirm final group size, hotel blocks, transport, guides, meals, academic content and cultural immersions
A26: Send final program services agreement | B26: P-22 | C26: =Legend!$C$12-22 -> 46125 | D26: Planning
A27: Prepare for in-person/online program orientation and safety briefing | B27: P-22 | C27: =Legend!$C$12-22 -> 46125 | D27: Planning | E27: Refer to India orientation PPT
A28: Create and share pre-departure guide | B28: P-22 | C28: =Legend!$C$12-22 -> 46125 | D28: Planning | E28: Refer to standard pre dep template
A29: Create checklist for delivery | B29: P-10 | C29: =Legend!$C$12-10 -> 46137 | D29: Delivery | E29: Refer to mastersheet for template
A30: Plan and prepare first aid kits and other relevant material specific to programs | B30: P-5 | C30: =Legend!$C$12-5 -> 46142 | D30: Delivery
A31: Print checklists and relevant documents | B31: P-5 | C31: =Legend!$C$12-5 -> 46142 | D31: Delivery
A32: Send post program invoice to the university | B32: PE+10 | C32: =Legend!$C$13+10 -> 46167 | D32: Delivery | E32: Enter Program end date + 7 days
A33: Send thank you notes to partner organizations / companies | B33: PE+5 | C33: =Legend!$C$13+5 -> 46162 | D33: Delivery | E33: Send thank you notes on the same day of the visit (could vary based on the work load)
A36: Pre-departure planning
A37: Name | B37: Timeframe (Date) | C37: Timeframe (Date) | D37: Milestone | E37: Notes | F37: Process # | G37: Timeline - Start | H37: Timeline - End
A38: Mandatory vendor service specification documentation | B38: P-22 | C38: =Legend!$C$12-22 -> 46125 | D38: Planning | E38: NEW: All limitations documented
A39: Complete program orientation for guides and local partners | B39: P-22 | C39: =Legend!$C$12-22 -> 46125 | D39: Planning | E39: Brief them about Authentica standards
A42: Triple Verification Protocol
A43: Name | B43: Timeframe (Date) | C43: Timeframe (Date) | D43: Milestone | E43: Notes | F43: Process # | G43: Timeline - Start | H43: Timeline - End
A44: Verify pre-program delivery checklist | B44: P-5 | C44: =Legend!$C$12-5 -> 46142 | D44: Planning | E44: Refer template
A46: Hotels
A47: Name | B47: Timeframe (Date) | C47: Timeframe (Date) | D47: Milestone | E47: Notes | F47: Process # | G47: Timeline - Start | H47: Timeline - End
A48: Block and sign contracts with chosen hotels and procure invoices with payment details | B48: W+1 | C48: =Legend!$C$9+1 -> 1 | D48: Planning | E48: As per updated numbers received from the university
...
