Workbook

Sheet Legend
A1: Category-wise steps for confirmed programs
A2: Legend for time-limits within which things need to be done:
A4: Symbol | B4: Meaning | C4: Date | D4: Notes | E4: Milestone
A5: R | B5: stands for date of receiving RFP | C5: 46082 | D5: Input actual date of receiving RFP | E5: Working on RFP
A6: R+ | B6: stands for no. of days after receiving RFP
A7: S | B7: stands for proposal submission date | C7: =$C$5+14 -> 46096 | D7: Input actual deadline of submitting proposal or Actual date of submitting proposal | E7: Working on RFP
A8: S-/+ | B8: stands for no. of days before/after proposal submission date
A9: C | B9: stands for date of confirmation (for repeat clients, this can be when they tell us group size) | C9: 46101 | D9: Input actual date of program confirmation | E9: Planning
A10: C+ | B10: stands for no. of days after confirmation/go-ahead received from client
A11: P | B11: stands for program dates | C11: 46130 | D11: Input actual program start date | E11: Delivery
A12: PE | B12: stands for program end date | C12: 46234 | D12: Input actual program end date | E12: Delivery
A13: P- | B13: stands for no. of days before program start
A14: P+ | B14: stands for no. of days after the program ends

Sheet Operations Process
A1: Operations Process (Proposal to Delivery)
A3: Action Items while sending proposals
A4: Name | B4: Timeframe (Date) | C4: Timeframe (Date) | D4: Milestone | E4: Notes | F4: Process # | G4: Timeline - Start | H4: Timeline - End
A5: Ensure sales hand-off template is filled; clarify doubts, if any before working on the proposal | B5: R | C5: =Legend!$C$5 -> 46082 | D5: Working on RFP
A6: Use itinerary elements template to detail out the requirements | B6: R+1 | C6: =Legend!$C$5+1 -> 46083 | D6: Working on RFP
A7: Use vendor template to reach out to DMCs etc. | B7: R+1 | C7: =Legend!$C$5+1 -> 46083 | D7: Working on RFP
A8: Decide FOC etc. terms with hotels | B8: R+7 | C8: =Legend!$C$5+7 -> 46089 | D8: Working on RFP
A9: Use hotel options, dining options etc. templates to save all information | B9: R+7 | C9: =Legend!$C$5+7 -> 46089 | D9: Working on RFP
A10: Document all vendor service limitations and requirements | B10: R+7 | C10: =Legend!$C$5+7 -> 46089 | D10: Working on RFP | E10: NEW: Capture luggage transfer limits, group size restrictions, etc.
A11: Verify accommodation standards meet university requirements (private bathrooms, accessibility) | B11: R+7 | C11: =Legend!$C$5+7 -> 46089 | D11: Working on RFP | E11: NEW: Based on Cats Hostel Madrid issue
A12: Complete work on costing sheet and proposal formats | B12: R+7 | C12: =Legend!$C$5+7 -> 46089 | D12: Working on RFP
A13: Include detailed transportation requirements template (airport transfers, public transit specifications) | B13: S-1 | C13: =Legend!$C$7-1 -> 46095 | D13: Working on RFP | E13: NEW: Based on Barcelona transit confusion
A14: Do a thorough proof-reading and cross-checking (with help from another team member) | B14: S-1 | C14: =Legend!$C$7-1 -> 46095 | D14: Working on RFP
A15: Ensure block on all hotels and important resources while sending proposals | B15: S | C15: =Legend!$C$7 -> 46096 | D15: Working on RFP | E15: ensure payments & cancellation are on agreeable terms
A16: Followup with client on the proposal status | B16: S+15 | C16: =Legend!$C$7+15 -> 46111 | D16: Working on RFP | E16: could vary
A19: Action Items after program confirmation
A20: Name | B20: Timeframe (Date) | C20: Timeframe (Date) | D20: Milestone | E20: Notes | F20: Process # | G20: Timeline - Start | H20: Timeline - End
A21: Send advance invoice | B21: P-90 | C21: =Legend!$C$11-90 -> 46040 | D21: Planning
A22: Create mastersheet and fill up all tabs with information till date | B22: C+1 | C22: =Legend!$C$9+1 -> 46102 | D22: Planning
A23: Implement triple verification system for all bookings | B23: C+3 | C23: =Legend!$C$9+3 -> 46104 | D23: Planning | E23: ENHANCED: Real-time tracking
A24: Set up Monday.com collaboration board with university stakeholders | B24: C+3 | C24: =Legend!$C$9+3 -> 46104 | D24: Planning | E24: ENHANCED: Real-time tracking
A25: Create and share googlesheets to collect information from client | B25: C+7 | C25: =Legend!$C$9+7 -> 46108 | D25: Planning
A26: Prepare orientation ppt / other such information (e.g. language workshop, empathy workshop etc.) | B26: P-30 | C26: =Legend!$C$11-30 -> 46100 | D26: Planning
A27: Send balance invoice | B27: P-30 | C27: =Legend!$C$11-30 -> 46100 | D27: Planning
A28: Update emergency action plan for the program | B28: P-30 | C28: =Legend!$C$11-30 -> 46100 | D28: Planning
A29: Establish clear protocols for mid-program change requests | B29: P-30 | C29: =Legend!$C$11-30 -> 46100 | D29: Planning | E29: NEW: Based on OSU budget change requests
A30: Create and share pre-dep information / dossier | B30: P-30 | C30: =Legend!$C$11-30 -> 46100 | D30: Planning
A31: Include comprehensive service limitations in student materials | B31: P-30 | C31: =Legend!$C$11-30 -> 46100 | D31: Planning | E31: ENHANCED: Luggage specs, transit rules
A32: Create checklist for delivery | B32: P-15 | C32: =Legend!$C$11-15 -> 46115 | D32: Delivery
A33: Continue updating mastersheet on regular basis | B33: P-7 | C33: =Legend!$C$11-7 -> 46123 | D33: Delivery
A34: Create documentation and communication plan | B34: P-7 | C34: =Legend!$C$11-7 -> 46123 | D34: Delivery
A35: Plan and prepare first aid kits and other relevant material specific to programs | B35: P-7 | C35: =Legend!$C$11-7 -> 46123 | D35: Delivery
A36: Print checklists and relevant documents | B36: P-15 | C36: =Legend!$C$11-1 -> 46129 | D36: Delivery
A37: Note any additional expenses beyond what we have invoiced for | B37: P | C37: =Legend!$C$11-7 -> 46123 | D37: Delivery | E37: sometimes things are added even before program
A38: Send payment links to individuals for single supp/extra nights/activities (e.g. baseball match) etc. | B38: P | C38: =Legend!$C$11-7 -> 46123 | D38: Delivery | E38: time-frame could vary
A39: Send invoice to client for additional expenses | B39: P+7 | C39: =Legend!$C$12 -> 46234 | D39: Delivery | E39: Enter Program end date + 7 days
A40: Send thank you notes to partner organizations / companies | B40: P+7 | C40: =Legend!$C$12 -> 46234 | D40: Delivery | E40: Send thank you notes on the same day of the visit (could vary based on the work load)
A43: Pre-departure planning
A44: Name | B44: Timeframe (Date) | C44: Timeframe (Date) | D44: Milestone | E44: Notes | F44: Process # | G44: Timeline - Start | H44: Timeline - End
A45: Mandatory vendor service specification documentation | B45: C+45 | C45: =Legend!$C$5+45 -> 46127 | D45: Working on RFP | E45: NEW: All limitations documented
...

Sheet Faculty Led Programs
A1: Operations Process (Proposal to Delivery)
A3: Action Items while sending proposals
A4: Name | B4: Timeframe (Date) | C4: Timeframe (Date) | D4: Milestone | E4: Notes | F4: Process # | G4: Timeline - Start | H4: Timeline - End
A5: Ensure sales hand-off template is filled; clarify doubts, if any before working on the proposal | B5: R | C5: =Legend!$C$5 -> 46082 | D5: Working on RFP
A6: Use itinerary elements template to detail out the requirements | B6: R+1 | C6: =Legend!$C$5+1 -> 46083 | D6: Working on RFP
A7: Get quotes from DMCs/hotels for program dates | B7: R+1 | C7: =Legend!$C$5+1 -> 46083 | D7: Working on RFP | E7: Using vendor templates
A8: Finalize hotel options for the proposal | B8: R+7 | C8: =Legend!$C$5+7 -> 46089 | D8: Working on RFP | E8: Using hotel sheet template
A9: Complete and review the costing sheet and proposal | B9: R+7 | C9: =Legend!$C$5+7 -> 46089 | D9: Working on RFP | E9: Use formats
A10: Block all proposed hotels and guides | B10: S | C10: =Legend!$C$7 -> 46096 | D10: Working on RFP | E10: ensure payments & cancellation are on agreeable terms
A11: Followup with client/sales on the proposal status to release or keep the blocks | B11: S+15 | C11: =Legend!$C$7+15 -> 46111 | D11: Working on RFP | E11: Proposal confirmation timeline could vary
A13: Action Items after proposal is won
A14: Name | B14: Timeframe (Date) | C14: Timeframe (Date) | D14: Milestone | E14: Notes | F14: Process # | G14: Timeline - Start | H14: Timeline - End
A15: Sign contracts with hotels and DMCs | B15: P-90 | C15: =Legend!$C$11-90 -> 46040 | D15: Planning | E15: timeframe could vary
A16: Followup with client/sales on program confirmation date | B16: P-90 | C16: =Legend!$C$11-90 -> 46040 | D16: Planning | E16: timeframe could vary
A18: Action Items after program confirmation
A19: Name | B19: Timeframe (Date) | C19: Timeframe (Date) | D19: Milestone | E19: Notes | F19: Process # | G19: Timeline - Start | H19: Timeline - End
A20: Send deposit invoice to university | B20: P-90 | C20: =Legend!$C$11-90 -> 46040 | D20: Planning | E20: Check proposal terms and conditions
A21: Create mastersheet | B21: C+1 | C21: =Legend!$C$9+1 -> 46102 | D21: Planning | E21: Use template and fill information on an on-going basis
A22: Set up Monday.com/google sheet for collaboration with all university stakeholders | B22: C+3 | C22: =Legend!$C$9+3 -> 46104 | D22: Planning | E22: ENHANCED: Real-time tracking
A23: Share participant data template to collect information (including scanned passport copies) | B23: C+7 | C23: =Legend!$C$9+7 -> 46108 | D23: Planning | E23: Use participant data template #to client
A24: Prepare for in-person/online program orientation and safety briefing | B24: P-30 | C24: =Legend!$C$11-30 -> 46100 | D24: Planning | E24: Refer to India orientation PPT
A25: Send balance invoice to university | B25: P-30 | C25: =Legend!$C$11-30 -> 46100 | D25: Planning
A26: Get confirmation on final service requirements from university | D26: Planning | E26: Confirm final group size, hotel blocks, transport, guides, meals, academic content and cultural immersions
A27: Send final program services agreement | C27: =Legend!$C$11-30 -> 46100 | D27: Planning
A28: Create and share pre-departure guide | B28: P-30 | C28: =Legend!$C$11-30 -> 46100 | D28: Planning | E28: Refer to standard pre dep template
A29: Create checklist for delivery | B29: P-15 | C29: =Legend!$C$11-15 -> 46115 | D29: Delivery | E29: Refer to mastersheet for template
A30: Plan and prepare first aid kits and other relevant material specific to programs | B30: P-7 | C30: =Legend!$C$11-7 -> 46123 | D30: Delivery
A31: Print checklists and relevant documents | B31: P-15 | C31: =Legend!$C$11-1 -> 46129 | D31: Delivery
A32: Send post program invoice to the university | B32: P+7 | C32: =Legend!$C$12 -> 46234 | D32: Delivery | E32: Enter Program end date + 7 days
A33: Send thank you notes to partner organizations / companies | B33: P+7 | C33: =Legend!$C$12 -> 46234 | D33: Delivery | E33: Send thank you notes on the same day of the visit (could vary based on the work load)
A36: Pre-departure planning
A37: Name | B37: Timeframe (Date) | C37: Timeframe (Date) | D37: Milestone | E37: Notes | F37: Process # | G37: Timeline - Start | H37: Timeline - End
A38: Mandatory vendor service specification documentation | B38: C+45 | C38: =Legend!$C$5+45 -> 46127 | D38: Working on RFP | E38: NEW: All limitations documented
A39: Complete program orientation for guides and local partners | B39: C+45 | C39: =Legend!$C$5+45 -> 46127 | D39: Working on RFP | E39: Brief them about Authentica standards
A42: Triple Verification Protocol
A43: Name | B43: Timeframe (Date) | C43: Timeframe (Date) | D43: Milestone | E43: Notes | F43: Process # | G43: Timeline - Start | H43: Timeline - End
A44: Verify pre-program delivery checklist | B44: P-7 | C44: =Legend!$C$11-7 -> 46123 | D44: Planning | E44: Refer template
A46: Hotels
A47: Name | B47: Timeframe (Date) | C47: Timeframe (Date) | D47: Milestone | E47: Notes | F47: Process # | G47: Timeline - Start | H47: Timeline - End
A48: Block and sign contracts with chosen hotels and procure invoices with payment details | B48: C+1 | C48: =Legend!$C$9+1 -> 46102 | D48: Planning | E48: As per updated numbers received from the university
...

Sheet Internships
A1: Operations Process (Proposal to Delivery)
A3: Action Items while sending proposals
A4: Name | B4: Timeframe (Date) | C4: Timeframe (Date) | D4: Milestone | E4: Notes | F4: Process # | G4: Timeline - Start | H4: Timeline - End
A5: Ensure sales hand-off template is filled; clarify doubts, if any before working on the proposal | B5: R | C5: =Legend!$C$5 -> 46082 | D5: Working on RFP
A6: Use itinerary elements template to detail out the requirements | B6: R+1 | C6: =Legend!$C$5+1 -> 46083 | D6: Working on RFP
A7: Get quotes from DMCs/hotels for program dates | B7: R+1 | C7: =Legend!$C$5+1 -> 46083 | D7: Working on RFP | E7: Using vendor templates
A8: Finalize hotel options for the proposal | B8: R+7 | C8: =Legend!$C$5+7 -> 46089 | D8: Working on RFP | E8: Using hotel sheet template
A9: Complete and review the costing sheet and proposal | B9: R+7 | C9: =Legend!$C$5+7 -> 46089 | D9: Working on RFP | E9: Use formats
A10: Block all proposed hotels and guides | B10: S | C10: =Legend!$C$7 -> 46096 | D10: Working on RFP | E10: ensure payments & cancellation are on agreeable terms
A11: Followup with client/sales on the proposal status to release or keep the blocks | B11: S+15 | C11: =Legend!$C$7+15 -> 46111 | D11: Working on RFP | E11: Proposal confirmation timeline could vary
A13: Action Items after proposal is won
A14: Name | B14: Timeframe (Date) | C14: Timeframe (Date) | D14: Milestone | E14: Notes | F14: Process # | G14: Timeline - Start | H14: Timeline - End
A15: Sign contracts with hotels and DMCs | B15: P-90 | C15: =Legend!$C$11-90 -> 46040 | D15: Planning | E15: timeframe could vary
A16: Followup with client/sales on program confirmation date | B16: P-90 | C16: =Legend!$C$11-90 -> 46040 | D16: Planning | E16: timeframe could vary
A18: Action Items after program confirmation
A19: Name | B19: Timeframe (Date) | C19: Timeframe (Date) | D19: Milestone | E19: Notes | F19: Process # | G19: Timeline - Start | H19: Timeline - End
A20: Send deposit invoice to university | B20: P-90 | C20: =Legend!$C$11-90 -> 46040 | D20: Planning | E20: Check proposal terms and conditions
A21: Create mastersheet | B21: C+1 | C21: =Legend!$C$9+1 -> 46102 | D21: Planning | E21: Use template and fill information on an on-going basis
A22: Set up Monday.com/google sheet for collaboration with all university stakeholders | B22: C+3 | C22: =Legend!$C$9+3 -> 46104 | D22: Planning | E22: ENHANCED: Real-time tracking
A23: Share participant data template to collect information (including scanned passport copies) | B23: C+7 | C23: =Legend!$C$9+7 -> 46108 | D23: Planning | E23: Use participant data template #to client
A24: Prepare for in-person/online program orientation and safety briefing | B24: P-30 | C24: =Legend!$C$11-30 -> 46100 | D24: Planning | E24: Refer to India orientation PPT
A25: Send balance invoice to university | B25: P-30 | C25: =Legend!$C$11-30 -> 46100 | D25: Planning
A26: Get confirmation on final service requirements from university | D26: Planning | E26: Confirm final group size, hotel blocks, transport, guides, meals, academic content and cultural immersions
A27: Send final program services agreement | C27: =Legend!$C$11-30 -> 46100 | D27: Planning
A28: Create and share pre-departure guide | B28: P-30 | C28: =Legend!$C$11-30 -> 46100 | D28: Planning | E28: Refer to standard pre dep template
A29: Create checklist for delivery | B29: P-15 | C29: =Legend!$C$11-15 -> 46115 | D29: Delivery | E29: Refer to mastersheet for template
A30: Plan and prepare first aid kits and other relevant material specific to programs | B30: P-7 | C30: =Legend!$C$11-7 -> 46123 | D30: Delivery
A31: Print checklists and relevant documents | B31: P-15 | C31: =Legend!$C$11-1 -> 46129 | D31: Delivery
A32: Send post program invoice to the university | B32: P+7 | C32: =Legend!$C$12 -> 46234 | D32: Delivery | E32: Enter Program end date + 7 days
A33: Send thank you notes to partner organizations / companies | B33: P+7 | C33: =Legend!$C$12 -> 46234 | D33: Delivery | E33: Send thank you notes on the same day of the visit (could vary based on the work load)
A36: Pre-departure planning
A37: Name | B37: Timeframe (Date) | C37: Timeframe (Date) | D37: Milestone | E37: Notes | F37: Process # | G37: Timeline - Start | H37: Timeline - End
A38: Mandatory vendor service specification documentation | B38: C+45 | C38: =Legend!$C$5+45 -> 46127 | D38: Working on RFP | E38: NEW: All limitations documented
A39: Complete program orientation for guides and local partners | B39: C+45 | C39: =Legend!$C$5+45 -> 46127 | D39: Working on RFP | E39: Brief them about Authentica standards
A42: Triple Verification Protocol
A43: Name | B43: Timeframe (Date) | C43: Timeframe (Date) | D43: Milestone | E43: Notes | F43: Process # | G43: Timeline - Start | H43: Timeline - End
A44: Verify pre-program delivery checklist | B44: P-7 | C44: =Legend!$C$11-7 -> 46123 | D44: Planning | E44: Refer template
A46: Hotels
A47: Name | B47: Timeframe (Date) | C47: Timeframe (Date) | D47: Milestone | E47: Notes | F47: Process # | G47: Timeline - Start | H47: Timeline - End
A48: Block and sign contracts with chosen hotels and procure invoices with payment details | B48: C+1 | C48: =Legend!$C$9+1 -> 46102 | D48: Planning | E48: As per updated numbers received from the university
...

Sheet QC Checklist
A3: Action Items while sending proposals
A4: Name | B4: Timeframe (Date) | C4: Timeframe (Date) | D4: Milestone | E4: Notes | F4: Process # | G4: Timeline - Start | H4: Timeline - End
A5: Document all vendor service limitations and requirements | B5: R+7 | C5: =Legend!$C$5+7 -> 46089 | D5: Working on RFP | E5: NEW: Capture luggage transfer limits, group size restrictions, etc.
A6: Verify accommodation standards meet university requirements (private bathrooms, accessibility) | B6: R+7 | C6: =Legend!$C$5+7 -> 46089 | D6: Working on RFP | E6: NEW: Based on Cats Hostel Madrid issue
A7: Include detailed transportation requirements template (airport transfers, public transit specifications) | B7: S-1 | C7: =Legend!$C$7-1 -> 46095 | D7: Working on RFP | E7: NEW: Based on Barcelona transit confusion
A8: Implement triple verification system for all bookings | B8: C+3 | C8: =Legend!$C$9+3 -> 46104 | D8: Planning | E8: ENHANCED: Real-time tracking
A9: Establish clear protocols for mid-program change requests | B9: P-30 | C9: =Legend!$C$11-30 -> 46100 | D9: Planning | E9: NEW: Based on OSU budget change requests Add this point to services agreement
A10: Include comprehensive service limitations in student materials | B10: P-30 | C10: =Legend!$C$11-30 -> 46100 | D10: Planning | E10: ENHANCED: Luggage specs, transit rules Add this point to services agreement
A11: Accessibility assessment for all activities and routes | B11: C+40 | C11: =Legend!$C$5+40 -> 46122 | D11: Working on RFP | E11: NEW: San Sebastian route equity issue
A12: Weather contingency planning for all group activities | B12: C+35 | C12: =Legend!$C$5+35 -> 46117 | D12: Working on RFP | E12: NEW: San Sebastian dinner issue
A13: Restaurant proximity verification (max 10min walk from accommodations) | B13: C+35 | C13: =Legend!$C$5+35 -> 46117 | D13: Working on RFP | E13: NEW: Spain group dinner locations
A15: Continue updating mastersheet on regular basis | B15: P-7 | C15: =Legend!$C$11-7 -> 46123 | D15: Delivery
A16: Note any additional expenses beyond what we have invoiced for | B16: P | C16: =Legend!$C$11-7 -> 46123 | D16: Delivery | E16: Update the "post program invoice" tab in the mastersheet
A19: Send payment links to individuals for single supp/extra nights/activities (e.g. baseball match) etc. | B19: P | C19: =Legend!$C$11-7 -> 46123 | D19: Delivery | E19: time-frame could vary
A22: Triple Verification Protocol
A23: Name | B23: Timeframe (Date) | C23: Timeframe (Date) | D23: Milestone | E23: Notes | F23: Process # | G23: Timeline - Start | H23: Timeline - End
A24: First verification: All bookings confirmed with vendors | B24: P-15 | C24: =Legend!$C$11-15 -> 46115 | D24: Planning | E24: NEW: Screenshot confirmations required
A25: Second verification: Room counts, amenity specifications | B25: P-7 | C25: =Legend!$C$11-7 -> 46123 | D25: Planning | E25: NEW: Private bathroom verification
A26: Third verification: Final headcount updates to all vendors | B26: P-2 | C26: =Legend!$C$11-2 -> 46128 | D26: Delivery | E26: NEW: Prevent overbooking issues
A27: Pre-program vendor briefing calls (hotels, transport, guides) | B27: P-2 | C27: =Legend!$C$11-2 -> 46128 | D27: Delivery | E27: NEW: 72-hour advance coordination
A28: Transit pass delivery confirmation (24hrs before first use) | B28: P-2 | C28: =Legend!$C$11-2 -> 46128 | D28: Delivery | E28: NEW: San Sebastian dinner issue prevention
A29: Driver briefing with printed itineraries in local language | B29: P-2 | C29: =Legend!$C$11-2 -> 46128 | D29: Delivery | E29: NEW: Spain bus coordination issue
A32: Hotels
A33: Ensure rooms are allocated as per requirement and sort out any issues with the rooms in discussion with the duty manager | B33: P-1 | C33: =Legend!$C$11-1 -> 46129 | D33: Delivery
A35: Guides
A36: Be in touch on a daily basis to ensure things are going as per plan / discuss necessary modifications | B36: P | C36: =Legend!$C$11 -> 46130 | D36: Delivery
A39: Meeting Rooms
A40: Re-confirm all arrangements | B40: P-1 | C40: =Legend!$C$11-1 -> 46129 | D40: Delivery
A42: Transport
A43: Get driver details and confirm he has correct placard and itinerary | B43: P-1 | C43: =Legend!$C$11-1 -> 46129 | D43: Delivery
A44: Ensure driver knows the route / addresses and ensure tips are paid at the end | B44: P | C44: =Legend!$C$11-30 -> 46100 | D44: Delivery | E44: to be done a day in advance
A45: Ensure tips are paid to each driver on the last day / EOD | B45: P | C45: =Legend!$C$11-30 -> 46100 | D45: Delivery
A47: Immersions
A48: Reconfirm all arrangements | B48: P-1 | C48: =Legend!$C$11-1 -> 46129 | D48: Delivery
A50: Org Visits
A51: Reconfirm visit | B51: P-15 | C51: =Legend!$C$11-1 -> 46129 | D51: Delivery
A52: Ensure group reaches 10 mins. before meeting time and driver is ready at the end of the meeting | B52: P | C52: =Legend!$C$11 -> 46130 | D52: Delivery
A53: Give gifts to our contacts | B53: P | C53: =Legend!$C$11 -> 46130 | D53: Delivery
A54: Send thank you notes to org contacts and collect feedback (if any) | B54: P | C54: =Legend!$C$11 -> 46130 | D54: Delivery | E54: within 24 hours of visit
A56: Daily Operations Protocol
...
